Workbook

Sheet Manual Metadata
A1: Pull Order | B1: QC | C1: Date | D1: m.Body | E1: v.Sperm | F1: l.Sperm | G1: t.Sperm | H1: w.Head | I1: w.Thorax | J1: d.Spermatheca | K1: Location
A2: =INDEX([1]Achieved!A$1:A$1048576,MATCH('Manual Metadata'!B2,[1]Achieved!B$1:B$1048576,0)) -> 1 | B2: QC 0381 | C2: 2017-02-01T00:00:00Z | D2: 238.2 | E2: 0.866 | F2: 3393854 | G2: 3919000 | H2: 4.075 | I2: 5.05 | J2: 1.2875404 | K2: =INDEX([1]PID!E$1:E$1048576,MATCH('Manual Metadata'!B2,[1]PID!A$1:A$1048576,0)) -> NCA
A3: =INDEX([1]Achieved!A$1:A$1048576,MATCH('Manual Metadata'!B3,[1]Achieved!B$1:B$1048576,0)) -> 2 | B3: QC 0382 | C3: 2017-02-01T00:00:00Z | D3: 209.7 | E3: 0.76033333 | F3: 3911661.6 | G3: 5144666.7 | H3: 3.812 | I3: 4.955 | J3: 1.3030956 | K3: =INDEX([1]PID!E$1:E$1048576,MATCH('Manual Metadata'!B3,[1]PID!A$1:A$1048576,0)) -> NCA
A4: =INDEX([1]Achieved!A$1:A$1048576,MATCH('Manual Metadata'!B4,[1]Achieved!B$1:B$1048576,0)) -> 3 | B4: QC 0383 | C4: 2017-02-01T00:00:00Z | D4: 220.6 | E4: 0.95633333 | F4: 4757120.8 | G4: 4974333.3 | H4: 3.958 | I4: 5.184 | J4: 1.410134 | K4: =INDEX([1]PID!E$1:E$1048576,MATCH('Manual Metadata'!B4,[1]PID!A$1:A$1048576,0)) -> NCA
A5: =INDEX([1]Achieved!A$1:A$1048576,MATCH('Manual Metadata'!B5,[1]Achieved!B$1:B$1048576,0)) -> 4 | B5: QC 0385 | C5: 2017-02-01T00:00:00Z | D5: 213.1 | E5: 0.92266667 | F5: 3026039.1 | G5: 3279666.7 | H5: 3.958 | I5: 4.963 | J5: 1.3784075 | K5: =INDEX([1]PID!E$1:E$1048576,MATCH('Manual Metadata'!B5,[1]PID!A$1:A$1048576,0)) -> NCA
A6: =INDEX([1]Achieved!A$1:A$1048576,MATCH('Manual Metadata'!B6,[1]Achieved!B$1:B$1048576,0)) -> 792 | B6: QC 0388 | C6: 2017-02-01T00:00:00Z | D6: 202.3 | E6: 0.70733333 | F6: 3671060 | G6: 5190000 | H6: 3.882 | I6: 4.963 | J6: 1.256892 | K6: =INDEX([1]PID!E$1:E$1048576,MATCH('Manual Metadata'!B6,[1]PID!A$1:A$1048576,0)) -> NCA
A7: =INDEX([1]Achieved!A$1:A$1048576,MATCH('Manual Metadata'!B7,[1]Achieved!B$1:B$1048576,0)) -> 5 | B7: QC 0389 | C7: 2017-02-01T00:00:00Z | D7: 205.6 | E7: 0.75133333 | F7: 2023841.6 | G7: 2693666.7 | H7: 3.882 | I7: 4.988 | J7: 1.3785615 | K7: =INDEX([1]PID!E$1:E$1048576,MATCH('Manual Metadata'!B7,[1]PID!A$1:A$1048576,0)) -> NCA
A8: =INDEX([1]Achieved!A$1:A$1048576,MATCH('Manual Metadata'!B8,[1]Achieved!B$1:B$1048576,0)) -> 6 | B8: QC 0440 | C8: 2017-03-20T00:00:00Z | D8: 223 | E8: 0.92833333 | F8: 3743349.4 | G8: 4032333.3 | H8: 3.8268156 | I8: 5.1536313 | J8: 1.2290999 | K8: =INDEX([1]PID!E$1:E$1048576,MATCH('Manual Metadata'!B8,[1]PID!A$1:A$1048576,0)) -> NC
A9: =INDEX([1]Achieved!A$1:A$1048576,MATCH('Manual Metadata'!B9,[1]Achieved!B$1:B$1048576,0)) -> 793 | B9: QC 0442 | C9: 2017-03-20T00:00:00Z | D9: 191.4 | E9: 0.904 | F9: 3778358.4 | G9: 4179600 | H9: 3.650838 | I9: 4.6312849 | J9: 1.1719147 | K9: =INDEX([1]PID!E$1:E$1048576,MATCH('Manual Metadata'!B9,[1]PID!A$1:A$1048576,0)) -> NC
A10: =INDEX([1]Achieved!A$1:A$1048576,MATCH('Manual Metadata'!B10,[1]Achieved!B$1:B$1048576,0)) -> 7 | B10: QC 0444 | C10: 2017-03-20T00:00:00Z | D10: 200.1 | E10: 0.86833333 | F10: 3945967.2 | G10: 4544300 | H10: 3.7625698 | I10: 4.849162 | J10: 1.2010711 | K10: =INDEX([1]PID!E$1:E$1048576,MATCH('Manual Metadata'!B10,[1]PID!A$1:A$1048576,0)) -> NC
A11: =INDEX([1]Achieved!A$1:A$1048576,MATCH('Manual Metadata'!B11,[1]Achieved!B$1:B$1048576,0)) -> 8 | B11: QC 0449 | C11: 2017-03-20T00:00:00Z | D11: 209.3 | E11: 0.883 | F11: 5074306.7 | G11: 5746666.7 | H11: 3.972067 | I11: 5.0418994 | J11: 1.2891155 | K11: =INDEX([1]PID!E$1:E$1048576,MATCH('Manual Metadata'!B11,[1]PID!A$1:A$1048576,0)) -> USA
A12: =INDEX([1]Achieved!A$1:A$1048576,MATCH('Manual Metadata'!B12,[1]Achieved!B$1:B$1048576,0)) -> 794 | B12: QC 0451 | C12: 2017-03-20T00:00:00Z | D12: 198.7 | E12: 0.929 | F12: 2595579.5 | G12: 2793950 | H12: 3.7122905 | I12: 4.9134078 | J12: 1.1898851 | K12: =INDEX([1]PID!E$1:E$1048576,MATCH('Manual Metadata'!B12,[1]PID!A$1:A$1048576,0)) -> USA
A13: =INDEX([1]Achieved!A$1:A$1048576,MATCH('Manual Metadata'!B13,[1]Achieved!B$1:B$1048576,0)) -> 9 | B13: QC 0453 | C13: 2017-03-20T00:00:00Z | D13: 196.8 | E13: 0.87633333 | F13: 6022162.7 | G13: 6872000 | H13: 3.8435754 | I13: 5.1201117 | J13: 1.2681832 | K13: =INDEX([1]PID!E$1:E$1048576,MATCH('Manual Metadata'!B13,[1]PID!A$1:A$1048576,0)) -> USA
... A301: =INDEX([1]Achieved!A$1:A$1048576,MATCH('Manual Metadata'!B301,[1]Achieved!B$1:B$1048576,0)) -> 246 | B301: QC 1472 | C301: 2019-08-21T15:34:28Z | D301: 204.3 | E301: 0.945 | F301: 5976666.7 | G301: 6320033.3 | H301: 3.9192201 | I301: 5.1532033 | J301: 1.2116626 | K301: =INDEX([1]PID!E$1:E$1048576,MATCH('Manual Metadata'!B301,[1]PID!A$1:A$1048576,0)) -> USA
A302: =INDEX([1]Achieved!A$1:A$1048576,MATCH('Manual Metadata'!B302,[1]Achieved!B$1:B$1048576,0)) -> 247 | B302: QC 1473 | C302: 2019-08-21T15:37:47Z | D302: 162.3 | E302: 0.85666667 | F302: 6940000 | G302: 8004333.3 | H302: 3.6072423 | I302: 4.8328691 | J302: NA | K302: =INDEX([1]PID!E$1:E$1048576,MATCH('Manual Metadata'!B302,[1]PID!A$1:A$1048576,0)) -> USA
A303: =INDEX([1]Achieved!A$1:A$1048576,MATCH('Manual Metadata'!B303,[1]Achieved!B$1:B$1048576,0)) -> 832 | B303: QC 1476 | C303: 2019-08-21T15:48:45Z | D303: 178 | E303: 0.87366667 | F303: 5616666.7 | G303: 6391333.3 | H303: 3.7493036 | I303: 5.0557103 | J303: 1.330107 | K303: =INDEX([1]PID!E$1:E$1048576,MATCH('Manual Metadata'!B303,[1]PID!A$1:A$1048576,0)) -> USA
A304: =INDEX([1]Achieved!A$1:A$1048576,MATCH('Manual Metadata'!B304,[1]Achieved!B$1:B$1048576,0)) -> 248 | B304: QC 1477 | C304: 2019-08-21T15:52:37Z | D304: 130 | E304: 0.81933333 | F304: 2311000 | G304: 2774333.3 | H304: 3.4679666 | I304: 4.5571031 | J304: 1.0561436 | K304: =INDEX([1]PID!E$1:E$1048576,MATCH('Manual Metadata'!B304,[1]PID!A$1:A$1048576,0)) -> USA
A305: =INDEX([1]Achieved!A$1:A$1048576,MATCH('Manual Metadata'!B305,[1]Achieved!B$1:B$1048576,0)) -> 833 | B305: QC 1478 | C305: 2019-08-21T15:55:31Z | D305: 195.7 | E305: 0.89233333 | F305: 5593333.3 | G305: 6221333.3 | H305: 3.6796657 | I305: 4.9387187 | J305: 1.257302 | K305: =INDEX([1]PID!E$1:E$1048576,MATCH('Manual Metadata'!B305,[1]PID!A$1:A$1048576,0)) -> USA
A306: =INDEX([1]Achieved!A$1:A$1048576,MATCH('Manual Metadata'!B306,[1]Achieved!B$1:B$1048576,0)) -> 249 | B306: QC 1479 | C306: 2019-08-21T15:59:37Z | D306: 185 | E306: 0.87933333 | F306: 3933333.3 | G306: 4488666.7 | H306: 3.7103064 | I306: 4.908078 | J306: 1.2533395 | K306: =INDEX([1]PID!E$1:E$1048576,MATCH('Manual Metadata'!B306,[1]PID!A$1:A$1048576,0)) -> USA
A307: =INDEX([1]Achieved!A$1:A$1048576,MATCH('Manual Metadata'!B307,[1]Achieved!B$1:B$1048576,0)) -> 250 | B307: QC 1481 | C307: 2019-08-27T10:49:08Z | D307: 227.3 | E307: 0.57266667 | F307: 1873333.3 | G307: 3262666.7 | H307: 3.789731 | I307: 4.7750611 | J307: 1.3484655 | K307: =INDEX([1]PID!E$1:E$1048576,MATCH('Manual Metadata'!B307,[1]PID!A$1:A$1048576,0)) -> OH
A308: =INDEX([1]Achieved!A$1:A$1048576,MATCH('Manual Metadata'!B308,[1]Achieved!B$1:B$1048576,0)) -> 834 | B308: QC 1482 | C308: 2019-08-28T15:17:10Z | D308: 197 | E308: 0.77733333 | F308: 7260000 | G308: 9263333.3 | H308: 3.8282548 | I308: 4.7091413 | J308: 1.1551242 | K308: =INDEX([1]PID!E$1:E$1048576,MATCH('Manual Metadata'!B308,[1]PID!A$1:A$1048576,0)) -> GA
A309: =INDEX([1]Achieved!A$1:A$1048576,MATCH('Manual Metadata'!B309,[1]Achieved!B$1:B$1048576,0)) -> 251 | B309: QC 1485 | C309: 2019-08-28T16:12:18Z | D309: 227.4 | E309: 0.878 | F309: 4196666.7 | G309: 4781333.3 | H309: 3.8393352 | I309: 4.8227147 | J309: 1.2907266 | K309: =INDEX([1]PID!E$1:E$1048576,MATCH('Manual Metadata'!B309,[1]PID!A$1:A$1048576,0)) -> GA
A310: =INDEX([1]Achieved!A$1:A$1048576,MATCH('Manual Metadata'!B310,[1]Achieved!B$1:B$1048576,0)) -> 252 | B310: QC 1486 | C310: 2019-08-28T16:12:18Z | D310: 184.2 | E310: 0.878 | F310: 4196666.7 | G310: 4781333.3 | H310: 3.7229917 | I310: 4.767313 | J310: 1.1991506 | K310: =INDEX([1]PID!E$1:E$1048576,MATCH('Manual Metadata'!B310,[1]PID!A$1:A$1048576,0)) -> GA
A311: =INDEX([1]Achieved!A$1:A$1048576,MATCH('Manual Metadata'!B311,[1]Achieved!B$1:B$1048576,0)) -> 835 | B311: QC 1490 | C311: 2019-08-28T16:25:19Z | D311: 220.5 | E311: 0.82066667 | F311: 6953333.3 | G311: 8463333.3 | H311: 3.8199446 | I311: 5.0941828 | J311: 1.2729332 | K311: =INDEX([1]PID!E$1:E$1048576,MATCH('Manual Metadata'!B311,[1]PID!A$1:A$1048576,0)) -> GA
A312: =INDEX([1]Achieved!A$1:A$1048576,MATCH('Manual Metadata'!B312,[1]Achieved!B$1:B$1048576,0)) -> 253 | B312: QC 1491 | C312: 2019-08-28T16:27:55Z | D312: 167.7 | E312: 0.704 | F312: 4436666.7 | G312: 6106666.7 | H312: 3.5927978 | I312: 4.7617728 | J312: 1.1188449 | K312: =INDEX([1]PID!E$1:E$1048576,MATCH('Manual Metadata'!B312,[1]PID!A$1:A$1048576,0)) -> GA
A313: =INDEX([1]Achieved!A$1:A$1048576,MATCH('Manual Metadata'!B313,[1]Achieved!B$1:B$1048576,0)) -> 254 | B313: QC 1495 | C313: 2019-08-28T16:39:46Z | D313: 212.6 | E313: 0.788 | F313: 3370000 | G313: 4237666.7 | H313: 3.6177285 | I313: 4.598338 | J313: 1.0857312 | K313: =INDEX([1]PID!E$1:E$1048576,MATCH('Manual Metadata'!B313,[1]PID!A$1:A$1048576,0)) -> GA
A314: =INDEX([1]Achieved!A$1:A$1048576,MATCH('Manual Metadata'!B314,[1]Achieved!B$1:B$1048576,0)) -> 255 | B314: QC 1502 | C314: 2019-08-28T17:04:39Z | D314: 197.6 | E314: 0.874 | F314: 6403333.3 | G314: 7365000 | H314: 3.7894737 | I314: 5.0415513 | J314: 1.2515937 | K314: =INDEX([1]PID!E$1:E$1048576,MATCH('Manual Metadata'!B314,[1]PID!A$1:A$1048576,0)) -> GA
... A377: =INDEX([1]Achieved!A$1:A$1048576,MATCH('Manual Metadata'!B377,[1]Achieved!B$1:B$1048576,0)) -> 306 | B377: QC 1720 | C377: 2020-07-15T17:07:22Z | D377: 156.4 | E377: 0.766 | F377: 2596666.7 | G377: 3270000 | H377: 3.622905 | I377: 4.6284916 | J377: 1.0973492 | K377: =INDEX([1]PID!E$1:E$1048576,MATCH('Manual Metadata'!B377,[1]PID!A$1:A$1048576,0)) -> NC
A378: =INDEX([1]Achieved!A$1:A$1048576,MATCH('Manual Metadata'!B378,[1]Achieved!B$1:B$1048576,0)) -> 307 | B378: QC 1721 | C378: 2020-07-21T15:25:30Z | D378: 221.4 | E378: 0.91833333 | F378: 10040000 | G378: 10880000 | H378: 3.877095 | I378: 4.8519553 | J378: NA | K378: =INDEX([1]PID!E$1:E$1048576,MATCH('Manual Metadata'!B378,[1]PID!A$1:A$1048576,0)) -> NY
A379: =INDEX([1]Achieved!A$1:A$1048576,MATCH('Manual Metadata'!B379,[1]Achieved!B$1:B$1048576,0)) -> 308 | B379: QC 1722 | C379: 2020-07-21T15:26:56Z | D379: 179.7 | E379: 0.868 | F379: 5636666.7 | G379: 6563333.3 | H379: 3.7234637 | I379: 4.7877095 | J379: NA | K379: =INDEX([1]PID!E$1:E$1048576,MATCH('Manual Metadata'!B379,[1]PID!A$1:A$1048576,0)) -> NY
A380: =INDEX([1]Achieved!A$1:A$1048576,MATCH('Manual Metadata'!B380,[1]Achieved!B$1:B$1048576,0)) -> 309 | B380: QC 1723 | C380: 2020-07-21T15:28:30Z | D380: 196 | E380: 0.88 | F380: 7920000 | G380: 8980000 | H380: 3.8296089 | I380: 4.9860335 | J380: NA | K380: =INDEX([1]PID!E$1:E$1048576,MATCH('Manual Metadata'!B380,[1]PID!A$1:A$1048576,0)) -> NY
A381: =INDEX([1]Achieved!A$1:A$1048576,MATCH('Manual Metadata'!B381,[1]Achieved!B$1:B$1048576,0)) -> 310 | B381: QC 1725 | C381: 2020-07-21T15:31:33Z | D381: 140.9 | E381: 0.847 | F381: 5263333.3 | G381: 6210000 | H381: 3.678771 | I381: 4.527933 | J381: NA | K381: =INDEX([1]PID!E$1:E$1048576,MATCH('Manual Metadata'!B381,[1]PID!A$1:A$1048576,0)) -> NY
A382: =INDEX([1]Achieved!A$1:A$1048576,MATCH('Manual Metadata'!B382,[1]Achieved!B$1:B$1048576,0)) -> 311 | B382: QC 1730 | C382: 2020-07-21T15:39:06Z | D382: 166.3 | E382: 0.86533333 | F382: 5770000 | G382: 6696666.7 | H382: 3.7905028 | I382: 4.6927374 | J382: 1.1436653 | K382: =INDEX([1]PID!E$1:E$1048576,MATCH('Manual Metadata'!B382,[1]PID!A$1:A$1048576,0)) -> NY
A383: =INDEX([1]Achieved!A$1:A$1048576,MATCH('Manual Metadata'!B383,[1]Achieved!B$1:B$1048576,0)) -> 312 | B383: QC 1732 | C383: 2020-07-21T15:41:59Z | D383: 165.9 | E383: 0.86066667 | F383: 7260000 | G383: 8433333.3 | H383: 3.9608939 | I383: 5.2653631 | J383: 1.2509657 | K383: =INDEX([1]PID!E$1:E$1048576,MATCH('Manual Metadata'!B383,[1]PID!A$1:A$1048576,0)) -> NY
A384: =INDEX([1]Achieved!A$1:A$1048576,MATCH('Manual Metadata'!B384,[1]Achieved!B$1:B$1048576,0)) -> 313 | B384: QC 1735 | C384: 2020-07-21T15:46:30Z | D384: 178.6 | E384: 0.85133333 | F384: 9216666.7 | G384: 10826667 | H384: 3.7709497 | I384: 5.0055866 | J384: 1.3122949 | K384: =INDEX([1]PID!E$1:E$1048576,MATCH('Manual Metadata'!B384,[1]PID!A$1:A$1048576,0)) -> NY
A385: =INDEX([1]Achieved!A$1:A$1048576,MATCH('Manual Metadata'!B385,[1]Achieved!B$1:B$1048576,0)) -> 314 | B385: QC 1739 | C385: 2020-07-21T15:53:47Z | D385: 150.9 | E385: 0.80366667 | F385: 4486666.7 | G385: 5573333.3 | H385: 3.7234637 | I385: 4.7877095 | J385: 1.2509657 | K385: =INDEX([1]PID!E$1:E$1048576,MATCH('Manual Metadata'!B385,[1]PID!A$1:A$1048576,0)) -> NY
A386: =INDEX([1]Achieved!A$1:A$1048576,MATCH('Manual Metadata'!B386,[1]Achieved!B$1:B$1048576,0)) -> 315 | B386: QC 1740 | C386: 2020-07-21T15:56:25Z | D386: 178.7 | E386: 0.83833333 | F386: 4530000 | G386: 5183333.3 | H386: 3.8743017 | I386: 5.0642458 | J386: 1.2509657 | K386: =INDEX([1]PID!E$1:E$1048576,MATCH('Manual Metadata'!B386,[1]PID!A$1:A$1048576,0)) -> NY
A387: =INDEX([1]Achieved!A$1:A$1048576,MATCH('Manual Metadata'!B387,[1]Achieved!B$1:B$1048576,0)) -> 316 | B387: QC 1743 | C387: 2020-07-28T14:47:24Z | D387: 209.5 | E387: 0.86966667 | F387: 3480000 | G387: 4006666.7 | H387: 3.9916897 | I387: 5.0277008 | J387: 1.2405698 | K387: =INDEX([1]PID!E$1:E$1048576,MATCH('Manual Metadata'!B387,[1]PID!A$1:A$1048576,0)) -> GA
A388: =INDEX([1]Achieved!A$1:A$1048576,MATCH('Manual Metadata'!B388,[1]Achieved!B$1:B$1048576,0)) -> 317 | B388: QC 1749 | C388: 2020-07-28T14:58:30Z | D388: 244.2 | E388: 0.63833333 | F388: 183166.67 | G388: 318000 | H388: 3.9612188 | I388: 4.9612188 | J388: 1.2898671 | K388: =INDEX([1]PID!E$1:E$1048576,MATCH('Manual Metadata'!B388,[1]PID!A$1:A$1048576,0)) -> GA
A389: =INDEX([1]Achieved!A$1:A$1048576,MATCH('Manual Metadata'!B389,[1]Achieved!B$1:B$1048576,0)) -> 318 | B389: QC 1750 | C389: 2020-07-28T15:00:28Z | D389: 259.9 | E389: 0.903 | F389: 8956666.7 | G389: 9886666.7 | H389: 3.9307479 | I389: 5.0221607 | J389: 1.2741989 | K389: =INDEX([1]PID!E$1:E$1048576,MATCH('Manual Metadata'!B389,[1]PID!A$1:A$1048576,0)) -> GA
...
